Workbook

Sheet Daily Data
A1: Site Name | B1: GSECL_Vasundhara | C1: =VLOOKUP(B1,Master!A2:B83,2,0) -> Vasundhara
A2: Date | B2: 46130
A3: Expected Generation | B3: =VLOOKUP($B$2,INDIRECT("'"&$C$1&"'!A4:P66"),2,FALSE) -> 92356
A4: Guaranteed Generation (kWh) | B4: =VLOOKUP($B$2,INDIRECT("'"&$C$1&"'!A4:P66"),3,FALSE) -> 88158
A5: Inverter Generation (kWh) | B5: =VLOOKUP($B$2,INDIRECT("'"&$C$1&"'!A4:P66"),4,FALSE) -> 95194
A6: ABT Meter Generation at Plant End (kWh) | B6: =VLOOKUP($B$2,INDIRECT("'"&$C$1&"'!A4:P66"),5,FALSE) -> 92400
A7: Generation difference (KWh) | B7: =VLOOKUP($B$2,INDIRECT("'"&$C$1&"'!A4:P66"),6,FALSE) -> 0.079811248
A8: DC-CUF | B8: =VLOOKUP($B$2,INDIRECT("'"&$C$1&"'!A4:P66"),7,FALSE) -> 0.21926018
A9: AC-CUF | B9: =VLOOKUP($B$2,INDIRECT("'"&$C$1&"'!A4:P66"),8,FALSE) -> 0.28331548
A10: Pvsyst Irradiation (kWh/m2) | B10: =VLOOKUP($B$2,INDIRECT("'"&$C$1&"'!A4:P66"),9,FALSE) -> 6.55
A11: Actual Irradiation (kWh/m2) | B11: =VLOOKUP($B$2,INDIRECT("'"&$C$1&"'!A4:P66"),10,FALSE) -> 6.6
A12: Radiation Difference (KWh/m2) | B12: =VLOOKUP($B$2,INDIRECT("'"&$C$1&"'!A4:P66"),11,FALSE) -> 0.0076335878
A13: PR | B13: =VLOOKUP($B$2,INDIRECT("'"&$C$1&"'!A4:P66"),12,FALSE) -> 0.79730975
A14: Plant Availability | B14: =VLOOKUP($B$2,INDIRECT("'"&$C$1&"'!A4:P66"),13,FALSE) -> 1
A15: Grid Availability | B15: =VLOOKUP($B$2,INDIRECT("'"&$C$1&"'!A4:P66"),14,FALSE) -> 0.9662
A16: Losses due to Grid Unavailability | B16: =VLOOKUP($B$2,INDIRECT("'"&$C$1&"'!A4:P66"),15,FALSE) -> 6084
A17: Losses due to Plant Unavailability | B17: =VLOOKUP($B$2,INDIRECT("'"&$C$1&"'!A4:P66"),16,FALSE)

Sheet Master
A1: Site Name | B1: Plant Code | C1: Date | D1: RM
A2: GHCL Phase-1_Musiri | B2: GHCL-1 | C2: 46113 | D2: Mehul Oza
A3: GHCL Phase-2_Musiri | B3: GHCL-2 | C3: 46114 | D3: Mehul Oza
A4: GHCL Phase-3_Ottapidaram | B4: Pollax | C4: 46115 | D4: Mehul Oza
A5: Thaiagarajar Mills_Ottapidaram | B5: GHCL-3 | C5: 46116 | D5: Mehul Oza
A6: Pollax solar solution_Otaapidaram | B6: TMILLS | C6: 46117 | D6: Mehul Oza
A7: VTM Limited | B7: VTM | C7: 46118 | D7: Mehul Oza
A8: Jothi Malleable & Microcast_TSU5_Karambakuddi | B8: JOTHI | C8: 46119 | D8: Mehul Oza
A9: GHCL Limited RT_Manaparai | B9: GHCL MANA | C9: 46120 | D9: Mehul Oza
A10: GHCL Limited RT_Paravai | B10: GHCL Para | C10: 46121 | D10: Mehul Oza
A11: GHCL Limited RT_Paravai-2 | B11: GHCL Para-2 | C11: 46122 | D11: Mehul Oza
A12: Suriya Spinning mills_Aviyoor | B12: SURIYA | C12: 46123 | D12: Mehul Oza
A13: Pantech Synergy_Aviyoor | B13: PANTECH | C13: 46124 | D13: Mehul Oza
... A25: Venus Denim-02 | B25: Venus Denim-02 | C25: 46136 | D25: Naresh Rajput
A26: Vishal Spintex | B26: Vishal Spintex | C26: =C25+1 -> 46137 | D26: Naresh Rajput
A27: Madura Textiles | B27: Madura textiles | C27: =C26+1 -> 46138 | D27: Naresh Rajput
A28: Alkyl Amines | B28: Alkyl Amines | C28: =C27+1 -> 46139 | D28: Naresh Rajput
A29: Pro-zeal green power five_Greenpro_KA | B29: PGP5 | C29: =C28+1 -> 46140 | D29: Mehul Oza
A30: Rishi FIBC_Bommalapura | B30: Rishi Bommalapura | C30: =C29+1 -> 46141 | D30: Mehul Oza
A31: Rishi FIBC_Tearakanambi | B31: RISHI Terakanambi | C31: =C30+1 -> 46142 | D31: Mehul Oza
A32: Automotive axels GO-1_TSU3_KA | B32: AAL GO-1 | C32: =C31+1 -> 46143 | D32: Mehul Oza
A33: Automotive axels GO-2_TSU3_KA | B33: AAL GO-2 | C33: =C32+1 -> 46144 | D33: Mehul Oza
A34: ACG_Tuljapur | B34: ACG_Tuljapur | C34: =C33+1 -> 46145 | D34: Kishan Mehta
A35: Aarti_Akola | B35: Aarti_Akola | C35: =C34+1 -> 46146 | D35: Kishan Mehta
A36: ACG_PZ4 | B36: ACG_PZ4 | C36: =C35+1 -> 46147 | D36: Kishan Mehta
A37: ACG_PAM | B37: ACG_PAM | C37: =C36+1 -> 46148 | D37: Kishan Mehta
... A62: Orito | B62: Orito | C62: =C61+1 -> 46173 | D62: Jahid Hussain
A63: Universal | B63: Universal | D63: Jahid Hussain
A64: Aditya-Arka | B64: Aditya-Arka | D64: Jahid Hussain
A65: Ajay cotspin | B65: Ajay cotspin | D65: Atul Patel
A66: Unitech cotspin | B66: Unitech cotspin | D66: Atul Patel
A67: Lincoln Pharma | B67: Lincoln Pharma | D67: Atul Patel
A68: Kamdhenu Yarn | B68: Kamdhenu Yarn | D68: Atul Patel
A69: Kikani Exports | B69: Kikani Exports | D69: Atul Patel
A70: Linde Engineering | B70: Linde Engineering | D70: Atul Patel
A71: Alembic Pharma Phase 1 | B71: Alembic Pharma Phase 1 | D71: Atul Patel
A72: Alembic Pharma Phase 2 | B72: Alembic Pharma Phase 2 | D72: Atul Patel
A73: Mark Alloys | B73: Mark Alloys | D73: Atul Patel
A74: Ujjaval Alloys | B74: Ujjaval Alloys | D74: Atul Patel
... A83: Vivekanand | B83: Vivekanand | D83: Jahid Hussain
...

Sheet May-26
A1: Site Name | B1: Ground Mounted/ Roof top | C1: State | D1: DC Capacity MWp | E1: AC Capacity MW | F1: Expected Generation | G1: Guaranteed Generation (kWh) | H1: Inverter Generation (kWh) | I1: ABT Meter Generation at Plant End (kWh) | J1: Generation difference (%) | K1: DC-CUF | L1: AC-CUF | M1: Pvsyst Irradiation (kWh/m2) | N1: Actual Irradiation (kWh/m2) | O1: Radiation Difference (%) | P1: PR | Q1: Plant Availability | R1: Grid Availability | S1: Losses due to Grid Unavailability | T1: Losses due to Plant Unavailability | U1: Remarks | Z1: MTD
A2: GHCL Phase-1_Musiri | B2: GM | C2: Tamilnadu | D2: {=INDIRECT("'" &Y2 & "'!D2")/1000} -> 10 | E2: {=INDIRECT("'" & Y2 & "'!h2")/1000} -> 7.5 | F2: {=INDIRECT("'"&$Y2&"'!b66:p66")} -> 274104 | G2: 226668 | H2: 222741.2 | I2: 219960 | J2: -0.029593944 | K2: 0.029938333 | L2: 0.039917778 | M2: 33.24 | N2: 31.69 | O2: -0.046630566 | P2: 0.70287536 | Q2: 1 | R2: 0.94651667 | S2: 19727 | T2: 0 | Y2: GHCL-1 | Z2: Vivekanand
A3: GHCL Phase-2_Musiri | B3: GM | C3: Tamilnadu | D3: {=INDIRECT("'" &Y3 & "'!D2")/1000} -> 10 | E3: {=INDIRECT("'" & Y3 & "'!h2")/1000} -> 7.5 | F3: {=INDIRECT("'"&$Y3&"'!b66:p66")} -> 270738 | G3: 226758 | H3: 189020.8 | I3: 186400 | J3: -0.17797829 | K3: 0.025406022 | L3: 0.033874695 | M3: 27.7 | N3: 25.32 | O3: -0.085920578 | P3: 0.74652765 | Q3: 1 | R3: 0.97598333 | S3: 6820 | T3: 0 | Y3: GHCL-2 | Z3: Prince
A4: GHCL Phase-3_Ottapidaram | B4: GM | C4: Tamilnadu | D4: {=INDIRECT("'" &Y4 & "'!D2")/1000} -> 21.2114 | E4: {=INDIRECT("'" & Y4 & "'!h2")/1000} -> 16 | F4: {=INDIRECT("'"&$Y4&"'!b66:p66")} -> 387788 | G4: 383576 | H4: 330477 | I4: 323640 | J4: -0.15625587 | K4: 0.020941075 | L4: 0.027761845 | M4: 22.6 | N4: 19.373 | O4: -0.14278761 | P4: 0.80422029 | Q4: 1 | R4: 1 | S4: 0 | T4: 0 | Y4: Pollax | Z4: Kiran
A5: Thaiagarajar Mills_Ottapidaram | B5: GM | C5: Tamilnadu | D5: {=INDIRECT("'" &Y5 & "'!D2")/1000} -> 9.998 | E5: {=INDIRECT("'" & Y5 & "'!h2")/1000} -> 7.67 | F5: {=INDIRECT("'"&$Y5&"'!b66:p66")} -> 181240 | G5: 150780 | H5: 164361 | I5: 159390 | J5: 0.057103064 | K5: 0.022095951 | L5: 0.028802519 | M5: 22.08 | N5: 20.692 | O5: -0.062862319 | P5: 0.79448037 | Q5: 1 | R5: 1 | S5: 0 | T5: 0 | Y5: GHCL-3 | Z5: Majethiya
A6: Pollax solar solution_Otaapidaram | B6: GM | C6: Tamilnadu | D6: {=INDIRECT("'" &Y6 & "'!D2")/1000} -> 15 | E6: {=INDIRECT("'" & Y6 & "'!h2")/1000} -> 12.095 | F6: {=INDIRECT("'"&$Y6&"'!b66:p66")} -> 263184 | G6: 259044 | H6: 234637 | I6: 231450 | J6: -0.10652244 | K6: 0.021024821 | L6: 0.026074602 | M6: 22.08 | N6: 19.559 | O6: -0.11417572 | P6: 0.799758 | Q6: 1 | R6: 1 | S6: 0 | T6: 0 | Y6: TMILLS | Z6: Centenary
A7: VTM Limited | B7: GM | C7: Tamilnadu | D7: {=INDIRECT("'" &Y7 & "'!D2")/1000} -> 2.205 | E7: {=INDIRECT("'" & Y7 & "'!h2")/1000} -> 1.76 | F7: {=INDIRECT("'"&$Y7&"'!b66:p66")} -> 42180 | G7: 39468 | H7: 35545 | I7: 35088 | J7: -0.11097598 | K7: 0.02166691 | L7: 0.027145192 | M7: 22.76 | N7: 19.745 | O7: -0.13246924 | P7: 0.8164184 | Q7: 1 | R7: 1 | S7: 0 | T7: 0 | Y7: VTM | Z7: Sainest
A8: Jothi Malleable & Microcast_TSU5_Karambakuddi | B8: GM | C8: Tamilnadu | D8: {=INDIRECT("'" &Y8 & "'!D2")/1000} -> 12.0006 | E8: {=INDIRECT("'" & Y8 & "'!h2")/1000} -> 9 | F8: {=INDIRECT("'"&$Y8&"'!b66:p66")} -> 224882.18 | G8: 208456 | H8: 231707.7 | I8: 225180 | J8: 0.080227962 | K8: 0.025951626 | L8: 0.034603898 | M8: 21.32 | N8: 23 | O8: 0.07879925 | P8: 0.83947868 | Q8: 1 | R8: 1 | S8: 0 | T8: 0 | Y8: JOTHI | Z8: Orito
A9: GHCL Limited RT_Manaparai | B9: RT | C9: Tamilnadu | D9: {=INDIRECT("'" &Y9 & "'!D2")/1000} -> 3.891 | E9: {=INDIRECT("'" & Y9 & "'!h2")/1000} -> 3.08 | F9: {=INDIRECT("'"&$Y9&"'!b66:p66")} -> 87075 | G9: 69445 | H9: 80925 | I9: 82332 | J9: 0.18557132 | K9: 0.027954295 | L9: 0.035314987 | M9: 28.7 | N9: 26.364 | O9: -0.081393728 | P9: 0.7888786 | Q9: 1 | R9: 0.9997 | S9: 0 | T9: 0 | Y9: GHCL MANA | Z9: Universal
A10: GHCL Limited RT_Paravai | B10: RT | C10: Tamilnadu | D10: {=INDIRECT("'" &Y10 & "'!D2")/1000} -> 1.297 | E10: {=INDIRECT("'" & Y10 & "'!h2")/1000} -> 1.1 | F10: {=INDIRECT("'"&$Y10&"'!b66:p66")} -> 28375 | G10: 28255 | H10: 20878 | I10: 21100 | J10: -0.25322952 | K10: 0.021635951 | L10: 0.025510753 | M10: 27.725 | N10: 25.088 | O10: -0.095112714 | P10: 0.64162736 | Q10: 1 | R10: 1 | S10: 0 | T10: 0 | Y10: GHCL Para | Z10: Aditya-Arka
A11: GHCL Limited RT_Paravai-2 | B11: RT | C11: Tamilnadu | D11: {=INDIRECT("'" &Y11 & "'!D2")/1000} -> 2.795 | E11: {=INDIRECT("'" & Y11 & "'!h2")/1000} -> 2.2 | F11: {=INDIRECT("'"&$Y11&"'!b66:p66")} -> 64420 | G11: 63710 | H11: 53502 | I11: 53617 | J11: -0.15842097 | K11: 0.025728548 | L11: 0.03268695 | M11: 28.5 | N11: 27.556 | O11: -0.033122807 | P11: 0.69465958 | Q11: 1 | R11: 1 | S11: 0 | T11: 0 | Y11: GHCL Para-2 | Z11: GHCL-1
A12: Suriya Spinning mills_Aviyoor | B12: GM | C12: Tamilnadu | D12: {=INDIRECT("'" &Y12 & "'!D2")/1000} -> 1.479 | E12: {=INDIRECT("'" & Y12 & "'!h2")/1000} -> 1.1 | F12: {=INDIRECT("'"&$Y12&"'!b66:p66")} -> 36822 | G12: 34824 | H12: 42096 | I12: 41628 | J12: 0.19538249 | K12: 0.038256014 | L12: 0.05143695 | M12: 32.16 | N12: 34.492 | O12: 0.072512438 | P12: 0.82519061 | Q12: 1 | R12: 0.99495 | S12: 77.62 | T12: 0 | Y12: SURIYA | Z12: GHCL-2
A13: Pantech Synergy_Aviyoor | B13: GM | C13: Tamilnadu | D13: {=INDIRECT("'" &Y13 & "'!D2")/1000} -> 2.608 | E13: {=INDIRECT("'" & Y13 & "'!h2")/1000} -> 1.9 | F13: {=INDIRECT("'"&$Y13&"'!b66:p66")} -> 71664 | G13: 67224 | H13: 73193 | I13: 72408 | J13: 0.077115316 | K13: 0.037721506 | L13: 0.051777731 | M13: 32.16 | N13: 32.813 | O13: 0.020304726 | P13: 0.85529518 | Q13: 1 | R13: 0.99495 | S13: 136.87 | T13: 0 | Y13: PANTECH | Z13: Pollax
A14: Parvathi Dyeing_Aviyoor | B14: GM | C14: Tamilnadu | D14: {=INDIRECT("'" &Y14 & "'!D2")/1000} -> 1.75 | E14: {=INDIRECT("'" & Y14 & "'!h2")/1000} -> 1.375 | F14: {=INDIRECT("'"&$Y14&"'!b66:p66")} -> 48258 | G14: 45582 | H14: 48741 | I14: 48512 | J14: 0.06427976 | K14: 0.037435484 | L14: 0.047645161 | M14: 32.16 | N14: 32.813 | O14: 0.020304726 | P14: 0.84880992 | Q14: 1 | R14: 0.99495 | S14: 91.84 | T14: 0 | Y14: PARVATHI | Z14: GHCL-3
A15: Bangalore internation airport limited | B15: GM | C15: Karnataka | D15: {=INDIRECT("'" &Y15 & "'!D2")/1000} -> 7.018 | E15: {=INDIRECT("'" & Y15 & "'!h2")/1000} -> 5.72 | F15: {=INDIRECT("'"&$Y15&"'!b66:p66")} -> 158440 | G15: 155140 | H15: 160237 | I15: 140420 | J15: -0.094882042 | K15: 0.03068856 | L15: 0.037652502 | M15: 29.8 | N15: 27.04 | O15: -0.09261745 | P15: 0.84438936 | Q15: 1 | R15: #DIV/0! | S15: 0 | T15: 0 | Y15: BIAL | Z15: TMILLS
A16: Bhargavi Renewables_Tharad | B16: GM | C16: Gujarat | D16: {=INDIRECT("'" &Y16 & "'!D2")/1000} -> 32.065 | E16: {=INDIRECT("'" & Y16 & "'!h2")/1000} -> 24.2 | F16: {=INDIRECT("'"&$Y16&"'!b66:p66")} -> 1133226 | G16: 1077024 | H16: 987153 | I16: 956100 | J16: -0.11227605 | K16: 0.053447912 | L16: 0.070818483 | M16: 42 | N16: 41.34 | O16: -0.015714286 | P16: 0.7447024 | Q16: 0.99718333 | R16: 1 | S16: 107988 | T16: 4039 | Y16: BRPL | Z16: VTM
A17: Pidilite Industries Limited_Pransla | B17: GM | C17: Gujarat | D17: {=INDIRECT("'" &Y17 & "'!D2")/1000} -> 1.805 | E17: {=INDIRECT("'" & Y17 & "'!h2")/1000} -> 1.582 | F17: {=INDIRECT("'"&$Y17&"'!b66:p66")} -> 62916 | G17: 60264 | H17: 76419 | I17: 76419 | J17: 0.26807049 | K17: 0.056905102 | L17: 0.064926492 | M17: 51.12 | N17: 50.017 | O17: -0.021576682 | P17: 0.84646013 | Q17: 1 | R17: 1 | S17: 0 | T17: 0 | Y17: Pidilite | Z17: JOTHI
A18: Greenbloom Energy_Balachadi | B18: GM | C18: Gujarat | D18: {=INDIRECT("'" &Y18 & "'!D2")/1000} -> 4.4 | E18: {=INDIRECT("'" & Y18 & "'!h2")/1000} -> 3.96 | F18: {=INDIRECT("'"&$Y18&"'!b66:p66")} -> 122870 | G18: 105980 | H18: 128258 | I18: 126000 | J18: 0.18890357 | K18: 0.039179497 | L18: 0.043532774 | M18: 35.4 | N18: 35.838 | O18: 0.012372881 | P18: 0.81336976 | Q18: 1 | R18: 0.998 | S18: 179 | T18: 0 | Y18: Greenbloom | Z18: SURIYA
A19: Isha Snacks_Varahi | B19: GM | C19: Gujarat | D19: {=INDIRECT("'" &Y19 & "'!D2")/1000} -> 1.124 | E19: {=INDIRECT("'" & Y19 & "'!h2")/1000} -> 0.88 | F19: {=INDIRECT("'"&$Y19&"'!b66:p66")} -> 18276 | G19: 15852 | H19: 0 | I19: 0 | J19: -1 | K19: 0 | L19: 0 | M19: 20.76 | N19: 0 | O19: -1 | P19: #DIV/0! | Q19: #DIV/0! | R19: #DIV/0! | S19: 0 | T19: 0 | Y19: Isha | Z19: PANTECH
A20: Enviro Vimalachal_Varahi | B20: GM | C20: Gujarat | D20: {=INDIRECT("'" &Y20 & "'!D2")/1000} -> 1.817 | E20: {=INDIRECT("'" & Y20 & "'!h2")/1000} -> 1.54 | F20: {=INDIRECT("'"&$Y20&"'!b66:p66")} -> 30258 | G20: 26274 | H20: 0 | I20: 0 | J20: -1 | K20: 0 | L20: 0 | M20: 21.39 | N20: 0 | O20: -1 | P20: #DIV/0! | Q20: #DIV/0! | R20: #DIV/0! | S20: 0 | T20: 0 | Y20: Enviro | Z20: PARVATHI
A21: Vimalachal Print & Packs_Varahi | B21: GM | C21: Gujarat | D21: {=INDIRECT("'" &Y21 & "'!D2")/1000} -> 2.525 | E21: {=INDIRECT("'" & Y21 & "'!h2")/1000} -> 1.98 | F21: {=INDIRECT("'"&$Y21&"'!b66:p66")} -> 44952 | G21: 39252 | H21: 0 | I21: 0 | J21: -1 | K21: 0 | L21: 0 | M21: 20.76 | N21: 0 | O21: -1 | P21: #DIV/0! | Q21: #DIV/0! | R21: #DIV/0! | S21: 0 | T21: 0 | Y21: Vimalachal | Z21: GHCL MANA
A22: GSECL_Vasundhara | B22: GM | C22: Gujarat | D22: {=INDIRECT("'" &Y22 & "'!D2")/1000} -> 18.09 | E22: {=INDIRECT("'" & Y22 & "'!h2")/1000} -> 14 | F22: =Vasundhara!B66 -> 0 | G22: =Vasundhara!C66 -> 0 | H22: =Vasundhara!D66 -> 0 | I22: =Vasundhara!E66 -> 0 | J22: =Vasundhara!F66 -> #DIV/0! | K22: =Vasundhara!G66 -> 0 | L22: =Vasundhara!H66 -> 0 | M22: =Vasundhara!I66 -> 0 | ... T22: =Vasundhara!P66 -> 0 | U22: =Vasundhara!Q34 | Y22: Vasundhara | Z22: GHCL Para
A23: Pudumjee | B23: GM | C23: Maharashtra | D23: {=INDIRECT("'" &Y23 & "'!D2")/1000} -> 21.5 | E23: {=INDIRECT("'" & Y23 & "'!h2")/1000} -> 15.4 | F23: =Pudumjee!P66 -> 0 | G23: =Pudumjee!Q66 -> 0 | H23: =Pudumjee!R66 -> 0 | I23: =Pudumjee!S66 -> 0 | J23: =Pudumjee!T66 -> 0 | K23: =Pudumjee!U66 -> 0 | L23: =Pudumjee!V66 -> 0 | M23: =Pudumjee!W66 -> 0 | ... T23: =Pudumjee!AD66 -> 0 | U23: =Pudumjee!Q34 | Y23: Pudumjee | Z23: GHCL Para-2
A24: Venus Denim-01 | B24: GM | C24: Gujarat | D24: {=INDIRECT("'" &Y24 & "'!D2")/1000} -> 3.3292 | E24: {=INDIRECT("'" & Y24 & "'!h2")/1000} -> 2.42 | F24: {=INDIRECT("'"&$Y24&"'!b66:p66")} -> 0 | G24: 0 | H24: 0 | I24: 0 | J24: #DIV/0! | K24: 0 | L24: 0 | M24: 0 | N24: 0 | O24: #DIV/0! | P24: #DIV/0! | Q24: #DIV/0! | R24: #DIV/0! | S24: 0 | T24: 0 | Y24: Venus Denim-01 | Z24: BIAL
A25: Venus Denim-02 | B25: GM | C25: Gujarat | D25: {=INDIRECT("'" &Y25 & "'!D2")/1000} -> 1.8007 | E25: {=INDIRECT("'" & Y25 & "'!h2")/1000} -> 1.54 | F25: {=INDIRECT("'"&$Y25&"'!b66:p66")} -> 0 | G25: 0 | H25: 0 | I25: 0 | J25: #DIV/0! | K25: 0 | L25: 0 | M25: 0 | N25: 0 | O25: #DIV/0! | P25: #DIV/0! | Q25: #DIV/0! | R25: #DIV/0! | S25: 0 | T25: 0 | Y25: Venus Denim-02 | Z25: BRPL
A26: Vishal Spintex | B26: GM | C26: Gujarat | D26: {=INDIRECT("'" &Y26 & "'!D2")/1000} -> 5.14808 | E26: {=INDIRECT("'" & Y26 & "'!h2")/1000} -> 3.96 | F26: {=INDIRECT("'"&$Y26&"'!b66:p66")} -> 0 | G26: 0 | H26: 0 | I26: 0 | J26: #DIV/0! | K26: 0 | L26: 0 | M26: 0 | N26: 0 | O26: #DIV/0! | P26: #DIV/0! | Q26: #DIV/0! | R26: #DIV/0! | S26: 0 | T26: 0 | Y26: Vishal Spintex | Z26: Pidilite
A27: Madura Textiles | B27: GM | C27: Gujarat | D27: {=INDIRECT("'" &Y27 & "'!D2")/1000} -> 65 | E27: {=INDIRECT("'" & Y27 & "'!h2")/1000} -> 50 | F27: {=INDIRECT("'"&$Y27&"'!b66:p66")} -> 0 | G27: 0 | H27: 0 | I27: 0 | J27: #DIV/0! | K27: 0 | L27: 0 | M27: 0 | N27: 0 | O27: #DIV/0! | P27: #DIV/0! | Q27: #DIV/0! | R27: #DIV/0! | S27: 0 | T27: 0 | Y27: Madura textiles | Z27: Greenbloom
A28: Alkyl Amines | B28: GM | C28: Maharashtra | D28: {=INDIRECT("'" &Y28 & "'!D2")/1000} -> 3.75 | E28: {=INDIRECT("'" & Y28 & "'!h2")/1000} -> 3 | F28: {=INDIRECT("'"&$Y28&"'!b66:p66")} -> 0 | G28: 0 | H28: 0 | I28: 0 | J28: #DIV/0! | K28: 0 | L28: 0 | M28: 0 | N28: 0 | O28: #DIV/0! | P28: #DIV/0! | Q28: #DIV/0! | R28: #DIV/0! | S28: 0 | T28: 0 | Y28: Alkyl Amines | Z28: Isha
A29: Pro-zeal green power five_Greenpro_KA | B29: GM | C29: Karnataka | D29: {=INDIRECT("'" &Y29 & "'!D2")/1000} -> 3.9284 | E29: {=INDIRECT("'" & Y29 & "'!h2")/1000} -> 2.86 | F29: {=INDIRECT("'"&$Y29&"'!b66:p66")} -> 56991 | G29: 50991 | H29: 0 | I29: 0 | J29: -1 | K29: 0 | L29: 0 | M29: 16.65 | N29: 0 | O29: -1 | P29: #DIV/0! | Q29: #DIV/0! | R29: #DIV/0! | S29: 0 | T29: 0 | Y29: PGP5 | Z29: Enviro
A30: Rishi FIBC_Bommalapura | B30: GM | C30: Karnataka | D30: {=INDIRECT("'" &Y30 & "'!D2")/1000} -> 3.717 | E30: {=INDIRECT("'" & Y30 & "'!h2")/1000} -> 3.3 | F30: {=INDIRECT("'"&$Y30&"'!b66:p66")} -> 57777 | G30: 52128 | H30: 0 | I30: 0 | J30: -1 | K30: 0 | L30: 0 | M30: 16.65 | N30: 0 | O30: -1 | P30: #DIV/0! | Q30: #DIV/0! | R30: #DIV/0! | S30: 0 | T30: 0 | Y30: Rishi Bommalapura | Z30: Vimalachal
A31: Rishi FIBC_Tearakanambi | B31: GM | C31: Karnataka | D31: {=INDIRECT("'" &Y31 & "'!D2")/1000} -> 4 | E31: {=INDIRECT("'" & Y31 & "'!h2")/1000} -> 3.2 | F31: {=INDIRECT("'"&$Y31&"'!b66:p66")} -> 54429 | G31: 52077 | H31: 0 | I31: 0 | J31: -1 | K31: 0 | L31: 0 | M31: 16.92 | N31: 0 | O31: -1 | P31: #DIV/0! | Q31: #DIV/0! | R31: #DIV/0! | S31: 0 | T31: 0 | Y31: RISHI Terakanambi | Z31: Vasundhara
A32: Automotive axels GO-1_TSU3_KA | B32: GM | C32: Karnataka | D32: {=INDIRECT("'" &Y32 & "'!D2")/1000} -> 6 | E32: {=INDIRECT("'" & Y32 & "'!h2")/1000} -> 4.9 | F32: {=INDIRECT("'"&$Y32&"'!b66:p66")} -> 81768 | G32: 78927 | H32: 0 | I32: 0 | J32: -1 | K32: 0 | L32: 0 | M32: 16.95 | N32: 0 | O32: -1 | P32: #DIV/0! | Q32: #DIV/0! | R32: #DIV/0! | S32: 0 | T32: 0 | Y32: AAL GO-1 | Z32: Pudumjee
A33: Automotive axels GO-2_TSU3_KA | B33: GM | C33: Karnataka | D33: {=INDIRECT("'" &Y33 & "'!D2")/1000} -> 6 | E33: {=INDIRECT("'" & Y33 & "'!h2")/1000} -> 4.5 | F33: {=INDIRECT("'"&$Y33&"'!b66:p66")} -> 82179 | G33: 79059 | H33: 0 | I33: 0 | J33: -1 | K33: 0 | L33: 0 | M33: 16.95 | N33: 0 | O33: -1 | P33: #DIV/0! | Q33: #DIV/0! | R33: #DIV/0! | S33: 0 | T33: 0 | Y33: AAL GO-2 | Z33: Venus Denim-01
A34: ACG_Tuljapur | B34: GM | C34: Maharashtra | D34: {=INDIRECT("'" &Y34 & "'!D2")/1000} -> 12.3 | E34: {=INDIRECT("'" & Y34 & "'!h2")/1000} -> 10.12 | F34: {=INDIRECT("'"&$Y34&"'!b66:p66")} -> 0 | G34: 0 | H34: 0 | I34: 0 | J34: #DIV/0! | K34: 0 | L34: 0 | M34: 0 | N34: 0 | O34: #DIV/0! | P34: #DIV/0! | Q34: #DIV/0! | R34: #DIV/0! | S34: 0 | T34: 0 | Y34: ACG_Tuljapur | Z34: Venus Denim-02
A35: Aarti_Akola | B35: GM | C35: Maharashtra | D35: {=INDIRECT("'" &Y35 & "'!D2")/1000} -> 20.998 | E35: {=INDIRECT("'" & Y35 & "'!h2")/1000} -> 14.85 | F35: {=INDIRECT("'"&$Y35&"'!b66:p66")} -> 0 | G35: 0 | H35: 0 | I35: 0 | J35: #DIV/0! | K35: 0 | L35: 0 | M35: 0 | N35: 0 | O35: #DIV/0! | P35: #DIV/0! | Q35: #DIV/0! | R35: #DIV/0! | S35: 0 | T35: 0 | Y35: Aarti_Akola | Z35: Vishal Spintex
A36: ACG_PZ4 | B36: GM | C36: Maharashtra | D36: {=INDIRECT("'" &Y36 & "'!D2")/1000} -> 8.39 | E36: {=INDIRECT("'" & Y36 & "'!h2")/1000} -> 6 | F36: {=INDIRECT("'"&$Y36&"'!b66:p66")} -> 0 | G36: 0 | H36: 0 | I36: 0 | J36: #DIV/0! | K36: 0 | L36: 0 | M36: 0 | N36: 0 | O36: #DIV/0! | P36: #DIV/0! | Q36: #DIV/0! | R36: #DIV/0! | S36: 0 | T36: 0 | Y36: ACG_PZ4 | Z36: Madura textiles
A37: ACG_PAM | B37: GM | C37: Maharashtra | D37: {=INDIRECT("'" &Y37 & "'!D2")/1000} -> 1.9 | E37: {=INDIRECT("'" & Y37 & "'!h2")/1000} -> 1.54 | F37: {=INDIRECT("'"&$Y37&"'!b66:p66")} -> 0 | G37: 0 | H37: 0 | I37: 0 | J37: #DIV/0! | K37: 0 | L37: 0 | M37: 0 | N37: 0 | O37: #DIV/0! | P37: #DIV/0! | Q37: #DIV/0! | R37: #DIV/0! | S37: 0 | T37: 0 | Y37: ACG_PAM | Z37: Alkyl Amines
A38: ACG_PGP3 | B38: GM | C38: Maharashtra | D38: {=INDIRECT("'" &Y38 & "'!D2")/1000} -> 6 | E38: {=INDIRECT("'" & Y38 & "'!h2")/1000} -> 3.9 | F38: {=INDIRECT("'"&$Y38&"'!b66:p66")} -> 0 | G38: 0 | H38: 0 | I38: 0 | J38: #DIV/0! | K38: 0 | L38: 0 | M38: 0 | N38: 0 | O38: #DIV/0! | P38: #DIV/0! | Q38: #DIV/0! | R38: #DIV/0! | S38: 0 | T38: 0 | Y38: ACG_PGP3 | Z38: PGP5
A39: Asahi Songwon_ Balasinor | B39: GM | C39: Gujarat | D39: {=INDIRECT("'" &Y39 & "'!D2")/1000} -> 4.9 | E39: {=INDIRECT("'" & Y39 & "'!h2")/1000} -> 3.96 | F39: {=INDIRECT("'"&$Y39&"'!b66:p66")} -> 823995.5 | G39: 783578.01 | H39: 110521 | I39: 107900 | J39: -0.86229833 | K39: 0.030316272 | L39: 0.037512558 | M39: 215.6019 | N39: 32.94 | O39: -0.84721842 | P39: 0.68473911 | Q39: 1 | R39: 1 | S39: 14611 | T39: 0 | Y39: Asahi Songwon_ Balasinor | Z39: Rishi Bommalapura
A40: August Energy_Akola | B40: GM | C40: Maharashtra | D40: {=INDIRECT("'" &Y40 & "'!D2")/1000} -> 5.9 | E40: {=INDIRECT("'" & Y40 & "'!h2")/1000} -> 3.96 | F40: {=INDIRECT("'"&$Y40&"'!b66:p66")} -> 0 | G40: 0 | H40: 0 | I40: 0 | J40: #DIV/0! | K40: 0 | L40: 0 | M40: 0 | N40: 0 | O40: #DIV/0! | P40: #DIV/0! | Q40: #DIV/0! | R40: #DIV/0! | S40: 0 | T40: 0 | Y40: August Energy_Akola | Z40: RISHI Terakanambi
...

Sheet Capcity
A3: Sum of AC Capacity | B3: Sum of DC Capacity MWp
A4: 428.337 | B4: 553.12944

Sheet Dashboard

Sheet Cuf
A3: Count of DC-CUF | B3: Count of AC-CUF
A4: 84 | B4: 84

Sheet April-26
A1: Site Name | B1: Month | C1: Ground Mounted/ Roof top | D1: State | E1: DC Capacity MWp | F1: AC Capacity MW | G1: Expected Generation | H1: Guaranteed Generation (kWh) | I1: Inverter Generation (kWh) | J1: ABT Meter Generation at Plant End (kWh) | K1: Generation difference (%) | L1: DC-CUF | M1: AC-CUF | N1: Pvsyst Irradiation (kWh/m2) | O1: Actual Irradiation (kWh/m2) | P1: Radiation Difference (%) | Q1: PR | R1: Plant Availability | S1: Grid Availability | T1: Losses due to Grid Unavailability | U1: Losses due to Plant Unavailability | V1: Remarks
A2: GHCL Phase-1_Musiri | B2: 46138 | C2: GM | D2: Tamilnadu | E2: 10 | F2: 7.5 | G2: 1441290 | H2: 1191870 | I2: 1300331 | J2: 1280640 | K2: 0.0745 | L2: 0.1806 | M2: 0.2408 | N2: 175 | O2: 189 | P2: 0.078 | Q2: 0.688 | R2: 1 | S2: 0.946 | T2: 114903 | U2: 0
A3: GHCL Phase-2_Musiri | B3: 46138 | C3: GM | D3: Tamilnadu | E3: 10 | F3: 7.5 | G3: 1425870 | H3: 1194240 | I3: 1330504 | J3: 1308400 | K3: 0.0956 | L3: 0.1848 | M3: 0.2464 | N3: 175 | O3: 189 | P3: 0.077 | Q3: 0.705 | R3: 1 | S3: 0.973 | T3: 61636 | U3: 1236
A4: GHCL Phase-3_Ottapidaram | B4: 46138 | C4: GM | D4: Tamilnadu | E4: 21.21 | F4: 16 | G4: 3138450 | H4: 3104370 | I4: 2791856 | J4: 2728080 | K4: -0.1212 | L4: 0.1828 | M4: 0.2179 | N4: 184 | O4: 165 | P4: -0.103 | Q4: 0.799 | R4: 1 | S4: 1 | T4: 0 | U4: 366
A5: Thaiagarajar Mills_Ottapidaram | B5: 46138 | C5: GM | D5: Tamilnadu | E5: 10 | F5: 7.67 | G5: 1463460 | H5: 1219200 | I5: 1342089 | J5: 1299150 | K5: 0.0656 | L5: 0.1864 | M5: 0.2188 | N5: 179 | O5: 177 | P5: -0.014 | Q5: 0.759 | R5: 0.999 | S5: 1 | T5: 0 | U5: 1458
A6: Pollax solar solution_Otaapidaram | B6: 46138 | C6: GM | D6: Tamilnadu | E6: 15 | F6: 12.1 | G6: 2128380 | H6: 2094870 | I6: 1939607 | J6: 1911150 | K6: -0.0877 | L6: 0.1796 | M6: 0.2051 | N6: 179 | O6: 162 | P6: -0.1 | Q6: 0.801 | R6: 1 | S6: 1 | T6: 0 | U6: 0
A7: VTM Limited | B7: 46138 | C7: GM | D7: Tamilnadu | E7: 2.21 | F7: 1.76 | G7: 338670 | H7: 316890 | I7: 286682 | J7: 282552 | K7: -0.1084 | L7: 0.1806 | M7: 0.2076 | N7: 183 | O7: 163 | P7: -0.112 | Q7: 0.799 | R7: 1 | S7: 1 | T7: 0 | U7: 0
A8: Jothi Malleable & Microcast_TSU5_Karambakuddi | B8: 46138 | C8: GM | D8: Tamilnadu | E8: 12 | F8: 9 | G8: 1816044 | H8: 1699496 | I8: 1870026 | J8: 1814400 | K8: 0.0676 | L8: 0.2164 | M8: 0.2565 | N8: 174 | O8: 186 | P8: 0.069 | Q8: 0.836 | R8: 1 | S8: 0.997 | T8: 7796 | U8: 0
A9: GHCL Limited RT_Manaparai | B9: 46138 | C9: RT | D9: Tamilnadu | E9: 3.89 | F9: 3.08 | G9: 550277 | H9: 541160 | I9: 520564 | J9: 493673 | K9: -0.0878 | L9: 0.1858 | M9: 0.2143 | N9: 179 | O9: 178 | P9: -0.007 | Q9: 0.751 | R9: 1 | S9: 0.997 | T9: 0 | U9: 0
A10: GHCL Limited RT_Paravai | B10: 46138 | C10: RT | D10: Tamilnadu | E10: 1.3 | F10: 1.1 | G10: 181404 | H10: 180441 | I10: 163670 | J10: 165448 | K10: -0.0831 | L10: 0.1753 | M10: 0.1954 | N10: 179 | O10: 174 | P10: -0.027 | Q10: 0.726 | R10: 1 | S10: 0.998 | T10: 0 | U10: 0
A11: GHCL Limited RT_Paravai-2 | B11: 46138 | C11: RT | D11: Tamilnadu | E11: 2.8 | F11: 2.2 | G11: 377310 | H11: 373140 | I11: 412256 | J11: 412722 | K11: 0.1061 | L11: 0.2049 | M11: 0.2393 | N11: 180 | O11: 185 | P11: 0.023 | Q11: 0.799 | R11: 1 | S11: 0.999 | T11: 0 | U11: 0
A12: Suriya Spinning mills_Aviyoor | B12: 46138 | C12: GM | D12: Tamilnadu | E12: 1.48 | F12: 1.1 | G12: 202885 | H12: 191883 | I12: 223939 | J12: 220836 | K12: 0.1509 | L12: 0.2103 | M12: 0.2524 | N12: 172 | O12: 192 | P12: 0.117 | Q12: 0.79 | R12: 1 | S12: 0.983 | T12: 6083 | U12: 0
A13: Pantech Synergy_Aviyoor | B13: 46138 | C13: GM | D13: Tamilnadu | E13: 2.61 | F13: 1.9 | G13: 389850 | H13: 365730 | I13: 389716 | J13: 383784 | K13: 0.0494 | L13: 0.2075 | M13: 0.2524 | N13: 172 | O13: 186 | P13: 0.083 | Q13: 0.804 | R13: 1 | S13: 0.985 | T13: 10064 | U13: 0
... A21: Vimalachal Print & Packs_Varahi | B21: 46138 | C21: GM | D21: Gujarat | E21: 2.53 | F21: 1.98 | G21: 475836 | H21: 415519 | I21: 413247 | J21: 406590 | K21: -0.0215 | L21: 0.2273 | M21: 0.2632 | N21: 217 | O21: 209 | P21: -0.037 | Q21: 0.783 | R21: 0.996 | S21: 0.969 | T21: 17421 | U21: 1352
A22: GSECL_Vasundhara | B22: 46138 | C22: GM | D22: Gujarat | E22: 18.09 | F22: 14 | G22: 2770680 | H22: 2644740 | I22: 5415420 | J22: 2691000 | K22: 0.0459 | L22: 0.2124 | M22: 0.2744 | N22: 199 | O22: 197 | P22: -0.008 | Q22: 0.775 | R22: 1 | S22: 0.945 | T22: 279144 | U22: 0 | V22: =Vasundhara!Q34
A23: Pudumjee | B23: 46138 | C23: GM | D23: Maharashtra | E23: 21.5 | F23: 15.4 | G23: 2328207 | H23: 2189481 | I23: 2410515 | J23: 2409540 | K23: 0.1005 | L23: 0.1557 | M23: 0.2174 | N23: 199 | O23: 142 | P23: -0.285 | Q23: 0.79 | R23: 0.998 | S23: 0.994 | T23: 14060 | U23: 4218 | V23: =Pudumjee!Q34
A24: Venus Denim-01 | B24: 46138 | C24: GM | D24: Gujarat | E24: 3.33 | F24: 2.42 | G24: 450892 | H24: 395968 | I24: 405353 | J24: 399060 | K24: 0.0078 | L24: 0.1691 | M24: 0.2326 | N24: 172 | O24: 163 | P24: -0.056 | Q24: 0.749 | R24: 0.991 | S24: 0.943 | T24: 34334 | U24: 3447
A25: Venus Denim-02 | B25: 46138 | C25: GM | D25: Gujarat | E25: 1.8 | F25: 1.54 | G25: 243800 | H25: 214107 | I25: 225776 | J25: 222320 | K25: 0.0384 | L25: 0.1741 | M25: 0.2036 | N25: 172 | O25: 163 | P25: -0.056 | Q25: 0.771 | R25: 0.991 | S25: 0.97 | T25: 9620 | U25: 1872
A26: Vishal Spintex | B26: 46138 | C26: GM | D26: Gujarat | E26: 5.15 | F26: 3.96 | G26: 855370 | H26: 760380 | I26: 801525 | J26: 781250 | K26: 0.0274 | L26: 0.2162 | M26: 0.2811 | N26: 211 | O26: 199 | P26: -0.056 | Q26: 0.783 | R26: 0.998 | S26: 0.958 | T26: 42836 | U26: 2630
A27: Madura Textiles | B27: 46138 | C27: GM | D27: Gujarat | E27: 65 | F27: 50 | G27: 7735659 | H27: 6923207 | I27: 7667930 | J27: 7452900 | K27: 0.0765 | L27: 0.1638 | M27: 0.213 | N27: 173 | O27: 155 | P27: -0.106 | Q27: 0.761 | R27: 1 | S27: 0.996 | T27: 378885 | U27: 2576
A28: Alkyl Amines | B28: 46138 | C28: GM | D28: Maharashtra | E28: 3.75 | F28: 3 | G28: 425720 | H28: 397700 | I28: 326224 | J28: 320040 | K28: -0.1953 | L28: 0.1208 | M28: 0.151 | N28: 135 | O28: 134 | P28: -0.008 | Q28: 0.651 | R28: 1 | S28: 0.844 | T28: 61759 | U28: 0
A29: Pro-zeal green power five_Greenpro_KA | B29: 46138 | C29: GM | D29: Karnataka | E29: 3.93 | F29: 2.86 | G29: 623300 | H29: 557681 | I29: 586167 | J29: 580730 | K29: 0.0413 | L29: 0.2072 | M29: 0.2545 | N29: 186 | O29: 184 | P29: -0.007 | Q29: 0.81 | R29: 0.995 | S29: 0.996 | T29: 8409 | U29: 1893
A30: Rishi FIBC_Bommalapura | B30: 46138 | C30: GM | D30: Karnataka | E30: 3.72 | F30: 3.3 | G30: 632445 | H30: 570599 | I30: 587316 | J30: 585140 | K30: 0.0255 | L30: 0.2195 | M30: 0.2367 | N30: 186 | O30: 183 | P30: -0.012 | Q30: 0.862 | R30: 0.995 | S30: 0.997 | T30: 1184 | U30: 1714
A31: Rishi FIBC_Tearakanambi | B31: 46138 | C31: GM | D31: Karnataka | E31: 4 | F31: 3.2 | G31: 573112 | H31: 548348 | I31: 514946 | J31: 512980 | K31: -0.0645 | L31: 0.1788 | M31: 0.2072 | N31: 182 | O31: 181 | P31: -0.005 | Q31: 0.711 | R31: 1 | S31: 0.946 | T31: 22938 | U31: 0
A32: Automotive axels GO-1_TSU3_KA | B32: 46138 | C32: GM | D32: Karnataka | E32: 6 | F32: 4.9 | G32: 847912 | H32: 818451 | I32: 869814 | J32: 850740 | K32: 0.0395 | L32: 0.2013 | M32: 0.2286 | N32: 177 | O32: 184 | P32: 0.043 | Q32: 0.787 | R32: 1 | S32: 0.998 | T32: 0 | U32: 556
A33: Automotive axels GO-2_TSU3_KA | B33: 46138 | C33: GM | D33: Karnataka | E33: 6 | F33: 4.5 | G33: 852173 | H33: 821081 | I33: 868918 | J33: 853740 | K33: 0.0398 | L33: 0.2011 | M33: 0.2426 | N33: 177 | O33: 183 | P33: 0.035 | Q33: 0.792 | R33: 1 | S33: 0.998 | T33: 0 | U33: 1066
A34: ACG_Tuljapur | B34: 46138 | C34: GM | D34: Maharashtra | E34: 12.3 | F34: 10.12 | G34: 1556230 | H34: 1517620 | I34: 1525862 | J34: 1495935 | K34: -0.0143 | L34: 0.1723 | M34: 0.1985 | N34: 172 | O34: 157 | P34: -0.087 | Q34: 0.792 | R34: 1 | S34: 1 | T34: 68285 | U34: 8421
A35: Aarti_Akola | B35: 46138 | C35: GM | D35: Maharashtra | E35: 21 | F35: 14.85 | G35: 2999178 | H35: 2317536 | I35: 2550625 | J35: 2531100 | K35: 0.0922 | L35: 0.1687 | M35: 0.2166 | N35: 173 | O35: 175 | P35: 0.008 | Q35: 0.695 | R35: 1 | S35: 0.959 | T35: 117502 | U35: 0
... A83: Vivekanand | B83: 46138 | C83: GM | D83: Gujarat | E83: 4.03 | F83: 3.15 | G83: 628481 | H83: 577704 | I83: 561839 | J83: 552440 | K83: -0.0437 | L83: 0.1934 | M83: 0.2477 | N83: 191 | O83: 173 | P83: -0.092 | Q83: 0.805 | R83: 1 | S83: 0.981 | T83: 28227 | U83: 0
A84: Kamal Textiles | B84: 46138 | C84: GM | D84: Gujarat | E84: 1.6 | F84: 1.32 | G84: 345000 | H84: 323550 | I84: 0 | J84: 0 | K84: -1 | L84: 0 | M84: 0 | N84: 268 | O84: 0 | P84: -1 | Q84: #DIV/0! | R84: #DIV/0! | S84: #DIV/0! | T84: 0 | U84: 0
A85: MBR Flexibles | B85: 46138 | C85: GM | D85: Gujarat | E85: 1.7 | F85: 1.32 | G85: 365010 | H85: 343140 | I85: 0 | J85: 0 | K85: -1 | L85: 0 | M85: 0 | N85: 268 | O85: 0 | P85: -1 | Q85: #DIV/0! | R85: #DIV/0! | S85: #DIV/0! | T85: 0 | U85: 0

Sheet Vivekanand
A1: Generation_Details_Plant-Name_4 mw Vivekanand costpin llp sami
A2: 46113 | B2: DC Capacity (kWp): | D2: 4034 | E2: AC capacity (kWp): | H2: 3150 | I2: COD : | K2: 45383
A3: Date | B3: Expected Generation | C3: Guaranteed Generation (kWh) | D3: Inverter Generation (kWh) | E3: ABT Meter Generation at Plant End (kWh) | F3: Generation difference (KWh) | G3: DC-CUF | H3: AC-CUF | I3: Pvsyst Irradiation (kWh/m2) | J3: Actual Irradiation (kWh/m2) | K3: Radiation Difference (KWh/m2) | L3: PR | M3: Plant Availability | N3: Grid Availability | O3: Losses due to Grid Unavailability | P3: Losses due to Plant Unavailability | Q3: Remarks
A4: =A2 -> 46113 | B4: 20949.363 | C4: 19256.808 | D4: 21274 | E4: 21000 | F4: =(IF(ISBLANK(E4),0,E4-C4))/C4 -> 0.090523437 | G4: =D4/($D$2*24) -> 0.21973641 | H4: =D4/($H$2*24) -> 0.28140212 | I4: 6.35 | J4: 6.42 | K4: =(IF(ISBLANK(J4),0,J4-I4))/I4 -> 0.011023622 | L4: =D4/($D$2*J4) -> 0.82144451 | M4: 1 | N4: 0.9842 | O4: 576 | P4: 0 | Q4: as per ALDC instructions 20% load curtailment
A5: =A4+1 -> 46114 | B5: 20949.363 | C5: 19256.808 | D5: 19336 | E5: 19040 | F5: =(IF(ISBLANK(E5),0,E5-C5))/C5 -> -0.011258751 | G5: =D5/($D$2*24) -> 0.19971905 | H5: =D5/($H$2*24) -> 0.2557672 | I5: 6.35 | J5: 5.78 | K5: =(IF(ISBLANK(J5),0,J5-I5))/I5 -> -0.08976378 | L5: =D5/($D$2*J5) -> 0.82928327 | M5: 1 | N5: 0.9928 | O5: 254 | P5: 0 | Q5: as per ALDC instructions 30% load curtailment
A6: =A5+1 -> 46115 | B6: 20949.363 | C6: 19256.808 | D6: 15953 | E6: 15720 | F6: =(IF(ISBLANK(E6),0,E6-C6))/C6 -> -0.18366531 | G6: =D6/($D$2*24) -> 0.16477648 | H6: =D6/($H$2*24) -> 0.21101852 | I6: 6.35 | J6: 4.77 | K6: =(IF(ISBLANK(J6),0,J6-I6))/I6 -> -0.2488189 | L6: =D6/($D$2*J6) -> 0.82906407 | M6: 1 | N6: 1 | O6: 0 | P6: 0
A7: =A6+1 -> 46116 | B7: 20949.363 | C7: 19256.808 | D7: 24120 | E7: 23680 | F7: =(IF(ISBLANK(E7),0,E7-C7))/C7 -> 0.229695 | G7: =D7/($D$2*24) -> 0.24913237 | H7: =D7/($H$2*24) -> 0.31904762 | I7: 6.35 | J7: 7.28 | K7: =(IF(ISBLANK(J7),0,J7-I7))/I7 -> 0.14645669 | L7: =D7/($D$2*J7) -> 0.82131552 | M7: 1 | N7: 1 | O7: 0 | P7: 0
A8: =A7+1 -> 46117 | B8: 20949.363 | C8: 19256.808 | D8: 22400 | E8: 22040 | F8: =(IF(ISBLANK(E8),0,E8-C8))/C8 -> 0.14453031 | G8: =D8/($D$2*24) -> 0.23136672 | H8: =D8/($H$2*24) -> 0.2962963 | I8: 6.35 | J8: 6.83 | K8: =(IF(ISBLANK(J8),0,J8-I8))/I8 -> 0.075590551 | L8: =D8/($D$2*J8) -> 0.81300164 | M8: 1 | N8: 0.98 | O8: 1242 | P8: 0 | Q8: as per ALDC instructions 30% load curtailment
A9: =A8+1 -> 46118 | B9: 20949.363 | C9: 19256.808 | D9: 22595 | E9: 22240 | F9: =(IF(ISBLANK(E9),0,E9-C9))/C9 -> 0.15491625 | G9: =D9/($D$2*24) -> 0.23338085 | H9: =D9/($H$2*24) -> 0.29887566 | I9: 6.35 | J9: 6.93 | K9: =(IF(ISBLANK(J9),0,J9-I9))/I9 -> 0.091338583 | L9: =D9/($D$2*J9) -> 0.80824535 | M9: 1 | N9: 0.97 | O9: 1643 | P9: 0 | Q9: as per ALDC instructions 30% load curtailment
A10: =A9+1 -> 46119 | B10: 20949.363 | C10: 19256.808 | D10: 12499 | E10: 12320 | F10: =(IF(ISBLANK(E10),0,E10-C10))/C10 -> -0.36022625 | G10: =D10/($D$2*24) -> 0.12910056 | H10: =D10/($H$2*24) -> 0.16533069 | I10: 6.35 | J10: 3.94 | K10: =(IF(ISBLANK(J10),0,J10-I10))/I10 -> -0.37952756 | L10: =D10/($D$2*J10) -> 0.78639936 | M10: 1 | N10: 0.95 | O10: 2086 | P10: 0 | Q10: as per ALDC instructions 50% load curtailment
A11: =A10+1 -> 46120 | B11: 20949.363 | C11: 19256.808 | D11: 17822 | E11: 17520 | F11: =(IF(ISBLANK(E11),0,E11-C11))/C11 -> -0.090191876 | G11: =D11/($D$2*24) -> 0.18408114 | H11: =D11/($H$2*24) -> 0.23574074 | I11: 6.35 | J11: 5.65 | K11: =(IF(ISBLANK(J11),0,J11-I11))/I11 -> -0.11023622 | L11: =D11/($D$2*J11) -> 0.7819376 | M11: 1 | N11: 0.95 | O11: 5520 | P11: 0 | Q11: as per ALDC instructions 50% load curtailment
A12: =A11+1 -> 46121 | B12: 20949.363 | C12: 19256.808 | D12: 21200 | E12: 20880 | F12: =(IF(ISBLANK(E12),0,E12-C12))/C12 -> 0.084291874 | G12: =D12/($D$2*24) -> 0.21897207 | H12: =D12/($H$2*24) -> 0.28042328 | I12: 6.35 | J12: 6.5 | K12: =(IF(ISBLANK(J12),0,J12-I12))/I12 -> 0.023622047 | L12: =D12/($D$2*J12) -> 0.80851226 | M12: 1 | N12: 0.98 | O12: 1516 | P12: 0 | Q12: as per ALDC instructions 40% load curtailment
A13: =A12+1 -> 46122 | B13: 20949.363 | C13: 19256.808 | D13: 22579 | E13: 22160 | F13: =(IF(ISBLANK(E13),0,E13-C13))/C13 -> 0.15076187 | G13: =D13/($D$2*24) -> 0.23321558 | H13: =D13/($H$2*24) -> 0.29866402 | I13: 6.35 | J13: 6.75 | K13: =(IF(ISBLANK(J13),0,J13-I13))/I13 -> 0.062992126 | L13: =D13/($D$2*J13) -> 0.82921097 | M13: 1 | N13: 0.98 | O13: 760 | P13: 0 | Q13: as per ALDC instructions 20% load curtailment
A14: =A13+1 -> 46123 | B14: 20949.363 | C14: 19256.808 | D14: 22642 | E14: 22280 | F14: =(IF(ISBLANK(E14),0,E14-C14))/C14 -> 0.15699344 | G14: =D14/($D$2*24) -> 0.2338663 | H14: =D14/($H$2*24) -> 0.29949735 | I14: 6.35 | J14: 6.82 | K14: =(IF(ISBLANK(J14),0,J14-I14))/I14 -> 0.074015748 | L14: =D14/($D$2*J14) -> 0.82298992 | M14: 1 | N14: 1 | O14: 0 | P14: 0
A15: =A14+1 -> 46124 | B15: 20949.363 | C15: 19256.808 | D15: 23345 | E15: 22920 | F15: =(IF(ISBLANK(E15),0,E15-C15))/C15 -> 0.19022844 | G15: =D15/($D$2*24) -> 0.2411275 | H15: =D15/($H$2*24) -> 0.3087963 | I15: 6.35 | J15: 7.03 | K15: =(IF(ISBLANK(J15),0,J15-I15))/I15 -> 0.10708661 | L15: =D15/($D$2*J15) -> 0.82319488 | M15: 1 | N15: 1 | O15: 0 | P15: 0
A16: =A15+1 -> 46125 | B16: 20949.363 | C16: 19256.808 | D16: 22676 | E16: 22280 | F16: =(IF(ISBLANK(E16),0,E16-C16))/C16 -> 0.15699344 | G16: =D16/($D$2*24) -> 0.23421748 | H16: =D16/($H$2*24) -> 0.29994709 | I16: 6.35 | J16: 6.77 | K16: =(IF(ISBLANK(J16),0,J16-I16))/I16 -> 0.066141732 | L16: =D16/($D$2*J16) -> 0.83031309 | M16: 1 | N16: 1 | O16: 0 | P16: 0
A17: =A16+1 -> 46126 | B17: 20949.363 | C17: 19256.808 | D17: 22461 | E17: 22040 | F17: =(IF(ISBLANK(E17),0,E17-C17))/C17 -> 0.14453031 | G17: =D17/($D$2*24) -> 0.23199678 | H17: =D17/($H$2*24) -> 0.29710317 | I17: 6.35 | J17: 6.99 | K17: =(IF(ISBLANK(J17),0,J17-I17))/I17 -> 0.1007874 | L17: =D17/($D$2*J17) -> 0.79655546 | M17: 1 | N17: 0.98 | O17: 1200 | P17: 0 | Q17: as per ALDC instructions 30% load curtailment
A18: =A17+1 -> 46127 | B18: 20949.363 | C18: 19256.808 | D18: 21265 | E18: 20920 | F18: =(IF(ISBLANK(E18),0,E18-C18))/C18 -> 0.086369062 | G18: =D18/($D$2*24) -> 0.21964345 | H18: =D18/($H$2*24) -> 0.28128307 | I18: 6.35 | J18: 6.67 | K18: =(IF(ISBLANK(J18),0,J18-I18))/I18 -> 0.050393701 | L18: =D18/($D$2*J18) -> 0.79032125 | M18: 1 | N18: 0.98 | O18: 1116 | P18: 0 | Q18: as per ALDC instructions 30% load curtailment
A19: =A18+1 -> 46128 | B19: 20949.363 | C19: 19256.808 | D19: 22078 | E19: 21720 | F19: =(IF(ISBLANK(E19),0,E19-C19))/C19 -> 0.12791281 | G19: =D19/($D$2*24) -> 0.22804082 | H19: =D19/($H$2*24) -> 0.29203704 | I19: 6.35 | J19: 6.95 | K19: =(IF(ISBLANK(J19),0,J19-I19))/I19 -> 0.094488189 | L19: =D19/($D$2*J19) -> 0.78747909 | M19: 1 | N19: 0.98 | O19: 904 | P19: 0 | Q19: as per ALDC instructions 30% load curtailment
A20: =A19+1 -> 46129 | B20: 20949.363 | C20: 19256.808 | D20: 21769 | E20: 21440 | F20: =(IF(ISBLANK(E20),0,E20-C20))/C20 -> 0.1133725 | G20: =D20/($D$2*24) -> 0.2248492 | H20: =D20/($H$2*24) -> 0.28794974 | I20: 6.35 | J20: 6.767 | K20: =(IF(ISBLANK(J20),0,J20-I20))/I20 -> 0.065669291 | L20: =D20/($D$2*J20) -> 0.79745541 | M20: 1 | N20: 0.98 | O20: 1358.57 | Q20: as per ALDC instructions 30% load curtailment
A21: =A20+1 -> 46130 | B21: 20949.363 | C21: 19256.808 | D21: 23431 | E21: 23000 | F21: =(IF(ISBLANK(E21),0,E21-C21))/C21 -> 0.19438281 | G21: =D21/($D$2*24) -> 0.24201578 | H21: =D21/($H$2*24) -> 0.30993386 | I21: 6.35 | J21: 7.264 | K21: =(IF(ISBLANK(J21),0,J21-I21))/I21 -> 0.14393701 | L21: =D21/($D$2*J21) -> 0.79961162 | M21: 1 | N21: 0.9868 | O21: 1016 | Q21: as per ALDC instructions 30% load curtailment
A22: =A21+1 -> 46131 | B22: 20949.363 | C22: 19256.808 | D22: 21698 | E22: 21320 | F22: =(IF(ISBLANK(E22),0,E22-C22))/C22 -> 0.10714094 | G22: =D22/($D$2*24) -> 0.22411585 | H22: =D22/($H$2*24) -> 0.28701058 | I22: 6.35 | J22: 6.804 | K22: =(IF(ISBLANK(J22),0,J22-I22))/I22 -> 0.071496063 | L22: =D22/($D$2*J22) -> 0.79053209 | M22: 1 | N22: 0.97 | O22: 1900 | Q22: as per ALDC instructions 20% load curtailment
A23: =A22+1 -> 46132 | B23: 20949.363 | C23: 19256.808 | D23: 22988 | E23: 22600 | F23: =(IF(ISBLANK(E23),0,E23-C23))/C23 -> 0.17361094 | G23: =D23/($D$2*24) -> 0.23744009 | H23: =D23/($H$2*24) -> 0.30407407 | I23: 6.35 | J23: 7.237 | K23: =(IF(ISBLANK(J23),0,J23-I23))/I23 -> 0.13968504 | L23: =D23/($D$2*J23) -> 0.78742051 | M23: 1 | N23: 0.98 | O23: 1306 | Q23: as per ALDC instructions 30% load curtailment
A24: =A23+1 -> 46133 | B24: 20949.363 | C24: 19256.808 | D24: 23173 | E24: 22760 | F24: =(IF(ISBLANK(E24),0,E24-C24))/C24 -> 0.18191969 | G24: =D24/($D$2*24) -> 0.23935093 | H24: =D24/($H$2*24) -> 0.30652116 | I24: 6.35 | J24: 7.357 | K24: =(IF(ISBLANK(J24),0,J24-I24))/I24 -> 0.15858268 | L24: =D24/($D$2*J24) -> 0.78081044 | M24: 1 | N24: 0.98 | O24: 1372 | Q24: as per ALDC instructions 30% load curtailment
A25: =A24+1 -> 46134 | B25: 20949.363 | C25: 19256.808 | D25: 22817 | E25: 22400 | F25: =(IF(ISBLANK(E25),0,E25-C25))/C25 -> 0.163225 | G25: =D25/($D$2*24) -> 0.23567386 | H25: =D25/($H$2*24) -> 0.30181217 | I25: 6.35 | J25: 7.139 | K25: =(IF(ISBLANK(J25),0,J25-I25))/I25 -> 0.12425197 | L25: =D25/($D$2*J25) -> 0.79229199 | M25: 1 | N25: 0.97 | O25: 1787 | Q25: as per ALDC instructions 30% load curtailment
A26: =A25+1 -> 46135 | B26: 20949.363 | C26: 19256.808 | D26: 23138 | E26: 22720 | F26: =(IF(ISBLANK(E26),0,E26-C26))/C26 -> 0.1798425 | G26: =D26/($D$2*24) -> 0.23898942 | H26: =D26/($H$2*24) -> 0.3060582 | I26: 6.35 | J26: 7.198 | K26: =(IF(ISBLANK(J26),0,J26-I26))/I26 -> 0.13354331 | L26: =D26/($D$2*J26) -> 0.79685276 | M26: 1 | N26: 0.98 | O26: 571 | Q26: as per ALDC instructions 20% load curtailment
A27: =A26+1 -> 46136 | B27: 20949.363 | C27: 19256.808 | D27: 23019 | E27: 22680 | F27: =(IF(ISBLANK(E27),0,E27-C27))/C27 -> 0.17776531 | G27: =D27/($D$2*24) -> 0.23776029 | H27: =D27/($H$2*24) -> 0.30448413 | I27: 6.35 | J27: 7.125 | K27: =(IF(ISBLANK(J27),0,J27-I27))/I27 -> 0.12204724 | L27: =D27/($D$2*J27) -> 0.80087676 | M27: 1 | N27: 0.99 | O27: 362 | Q27: as per ALDC instructions 20% load curtailment
A28: =A27+1 -> 46137 | B28: 20949.363 | C28: 19256.808 | D28: 22956 | E28: 22600 | F28: =(IF(ISBLANK(E28),0,E28-C28))/C28 -> 0.17361094 | G28: =D28/($D$2*24) -> 0.23710957 | H28: =D28/($H$2*24) -> 0.30365079 | I28: 6.35 | J28: 6.925 | K28: =(IF(ISBLANK(J28),0,J28-I28))/I28 -> 0.090551181 | L28: =D28/($D$2*J28) -> 0.82175157 | M28: 1
A29: =A28+1 -> 46138 | B29: 20949.363 | C29: 19256.808 | D29: 22605 | E29: 22160 | F29: =(IF(ISBLANK(E29),0,E29-C29))/C29 -> 0.15076187 | G29: =D29/($D$2*24) -> 0.23348413 | H29: =D29/($H$2*24) -> 0.29900794 | I29: 6.35 | J29: 7.032 | K29: =(IF(ISBLANK(J29),0,J29-I29))/I29 -> 0.10740157 | L29: =D29/($D$2*J29) -> 0.79687418 | M29: 1 | N29: 0.97 | O29: 1737 | Q29: as per ALDC instructions 40% load curtailment
A30: =A29+1 -> 46139 | B30: 20949.363 | C30: 19256.808 | F30: =(IF(ISBLANK(E30),0,E30-C30))/C30 -> 0 | G30: =D30/($D$2*24) -> 0 | H30: =D30/($H$2*24) -> 0 | I30: 6.35 | K30: =(IF(ISBLANK(J30),0,J30-I30))/I30 -> 0 | L30: =D30/($D$2*J30) -> #DIV/0!
A31: =A30+1 -> 46140 | B31: 20949.363 | C31: 19256.808 | F31: =(IF(ISBLANK(E31),0,E31-C31))/C31 -> 0 | G31: =D31/($D$2*24) -> 0 | H31: =D31/($H$2*24) -> 0 | I31: 6.35 | K31: =(IF(ISBLANK(J31),0,J31-I31))/I31 -> 0 | L31: =D31/($D$2*J31) -> #DIV/0!
A32: =A31+1 -> 46141 | B32: 20949.363 | C32: 19256.808 | F32: =(IF(ISBLANK(E32),0,E32-C32))/C32 -> 0 | G32: =D32/($D$2*24) -> 0 | H32: =D32/($H$2*24) -> 0 | I32: 6.35 | K32: =(IF(ISBLANK(J32),0,J32-I32))/I32 -> 0 | L32: =D32/($D$2*J32) -> #DIV/0!
A33: =A32+1 -> 46142 | B33: 20949.363 | C33: 19256.808 | F33: =(IF(ISBLANK(E33),0,E33-C33))/C33 -> 0 | G33: =D33/($D$2*24) -> 0 | H33: =D33/($H$2*24) -> 0 | I33: 6.35 | K33: =(IF(ISBLANK(J33),0,J33-I33))/I33 -> 0 | L33: =D33/($D$2*J33) -> #DIV/0!
A34: 46113 | B34: =SUM(B4:B33) -> 628480.89 | C34: =SUM(C4:C33) -> 577704.23 | D34: =SUM(D4:D33) -> 561839 | E34: =SUM(E4:E33) -> 552440 | F34: =(IF(ISBLANK(E34),0,E34-C34))/C34 -> -0.043732115 | G34: =AVERAGE(G4:G33) -> 0.19343876 | H34: =AVERAGE(H4:H33) -> 0.24772443 | I34: =SUM(I4:I33) -> 190.5 | J34: =SUM(J4:J33) -> 172.928 | K34: =(IF(ISBLANK(J34),0,J34-I34))/I34 -> -0.09224147 | L34: =D34/($D$2*J34) -> 0.80539823 | M34: =AVERAGE(M4:M33) -> 1 | N34: =AVERAGE(N4:N33) -> 0.981352 | O34: =SUM(O4:O33) -> 28226.57 | P34: =SUM(P4:P33) -> 0
A35: 46143 | F35: =(IF(ISBLANK(E35),0,E35-C35))/C35 -> #DIV/0! | G35: =D35/($D$2*24) -> 0 | H35: =D35/($H$2*24) -> 0 | K35: =(IF(ISBLANK(J35),0,J35-I35))/I35 -> #DIV/0! | L35: =D35/($D$2*J35) -> #DIV/0!
A36: =A35+1 -> 46144 | F36: =(IF(ISBLANK(E36),0,E36-C36))/C36 -> #DIV/0! | G36: =D36/($D$2*24) -> 0 | H36: =D36/($H$2*24) -> 0 | K36: =(IF(ISBLANK(J36),0,J36-I36))/I36 -> #DIV/0! | L36: =D36/($D$2*J36) -> #DIV/0!
A37: =A36+1 -> 46145 | F37: =(IF(ISBLANK(E37),0,E37-C37))/C37 -> #DIV/0! | G37: =D37/($D$2*24) -> 0 | H37: =D37/($H$2*24) -> 0 | K37: =(IF(ISBLANK(J37),0,J37-I37))/I37 -> #DIV/0! | L37: =D37/($D$2*J37) -> #DIV/0!
A38: =A37+1 -> 46146 | F38: =(IF(ISBLANK(E38),0,E38-C38))/C38 -> #DIV/0! | G38: =D38/($D$2*24) -> 0 | H38: =D38/($H$2*24) -> 0 | K38: =(IF(ISBLANK(J38),0,J38-I38))/I38 -> #DIV/0! | L38: =D38/($D$2*J38) -> #DIV/0!
A39: =A38+1 -> 46147 | F39: =(IF(ISBLANK(E39),0,E39-C39))/C39 -> #DIV/0! | G39: =D39/($D$2*24) -> 0 | H39: =D39/($H$2*24) -> 0 | K39: =(IF(ISBLANK(J39),0,J39-I39))/I39 -> #DIV/0! | L39: =D39/($D$2*J39) -> #DIV/0!
A40: =A39+1 -> 46148 | F40: =(IF(ISBLANK(E40),0,E40-C40))/C40 -> #DIV/0! | G40: =D40/($D$2*24) -> 0 | H40: =D40/($H$2*24) -> 0 | K40: =(IF(ISBLANK(J40),0,J40-I40))/I40 -> #DIV/0! | L40: =D40/($D$2*J40) -> #DIV/0!
...

Sheet Prince
A1: Generation Details_Prince Spinners_Mujpur_GJ.
A2: 46113 | B2: DC Capacity (kWp): | D2: 4809 | E2: AC capacity (kWp): | H2: 3850 | I2: COD : | K2: 30-03-2024
A3: Date | B3: Expected Generation | C3: Guaranteed Generation (kWh) | D3: Inverter Generation (kWh) | E3: ABT Meter Generation at Plant End (kWh) | F3: Generation difference (KWh) | G3: DC-CUF | H3: AC-CUF | I3: Pvsyst Irradiation (kWh/m2) | J3: Actual Irradiation (kWh/m2) | K3: Radiation Difference (KWh/m2) | L3: PR | M3: Plant Availability | N3: Grid Availability | O3: Losses due to Grid Unavailability | P3: Losses due to Plant Unavailability | Q3: Remarks
A4: =A2 -> 46113 | B4: 27440 | C4: 20057 | D4: 27854 | E4: 27300 | F4: =(IF(ISBLANK(E4),0,E4-C4))/C4 -> 0.36112081 | G4: =D4/($D$2*24) -> 0.24133569 | H4: =D4/($H$2*24) -> 0.30145022 | I4: 6.49 | J4: 6.751 | K4: =(IF(ISBLANK(J4),0,J4-I4))/I4 -> 0.040215716 | L4: =D4/($D$2*J4) -> 0.85795535 | M4: 1 | N4: 1 | O4: 0 | P4: 0
A5: =A4+1 -> 46114 | B5: 27440 | C5: 20057 | D5: 26487 | E5: 25950 | F5: =(IF(ISBLANK(E5),0,E5-C5))/C5 -> 0.29381263 | G5: =D5/($D$2*24) -> 0.22949158 | H5: =D5/($H$2*24) -> 0.28665584 | I5: 6.49 | J5: 6.368 | K5: =(IF(ISBLANK(J5),0,J5-I5))/I5 -> -0.018798151 | L5: =D5/($D$2*J5) -> 0.86491801 | M5: 1 | N5: 1 | O5: 0 | P5: 0
A6: =A5+1 -> 46115 | B6: 27440 | C6: 20057 | D6: 20169 | E6: 19850 | F6: =(IF(ISBLANK(E6),0,E6-C6))/C6 -> -0.010320586 | G6: =D6/($D$2*24) -> 0.17475047 | H6: =D6/($H$2*24) -> 0.21827922 | I6: 6.49 | J6: 4.76 | K6: =(IF(ISBLANK(J6),0,J6-I6))/I6 -> -0.26656394 | L6: =D6/($D$2*J6) -> 0.8810948 | M6: 1 | N6: 1 | O6: 0 | P6: 0
A7: =A6+1 -> 46116 | B7: 27440 | C7: 20057 | D7: 30494 | E7: 29800 | F7: =(IF(ISBLANK(E7),0,E7-C7))/C7 -> 0.48576557 | G7: =D7/($D$2*24) -> 0.26420947 | H7: =D7/($H$2*24) -> 0.33002165 | I7: 6.49 | J7: 7.304 | K7: =(IF(ISBLANK(J7),0,J7-I7))/I7 -> 0.12542373 | L7: =D7/($D$2*J7) -> 0.86815817 | M7: 1 | N7: 1 | O7: 0 | P7: 0
A8: =A7+1 -> 46117 | B8: 27440 | C8: 20057 | D8: 26661 | E8: 26150 | F8: =(IF(ISBLANK(E8),0,E8-C8))/C8 -> 0.30378421 | G8: =D8/($D$2*24) -> 0.23099917 | H8: =D8/($H$2*24) -> 0.28853896 | I8: 6.49 | J8: 7.035 | K8: =(IF(ISBLANK(J8),0,J8-I8))/I8 -> 0.083975347 | L8: =D8/($D$2*J8) -> 0.78805686 | M8: 1 | N8: 0.9375 | O8: 2668 | P8: 0 | Q8: 30% Load shedding message received from ALDC
A9: =A8+1 -> 46118 | B9: 27440 | C9: 20057 | D9: 27939 | E9: 27350 | F9: =(IF(ISBLANK(E9),0,E9-C9))/C9 -> 0.3636137 | G9: =D9/($D$2*24) -> 0.24207216 | H9: =D9/($H$2*24) -> 0.30237013 | I9: 6.49 | J9: 7.334 | K9: =(IF(ISBLANK(J9),0,J9-I9))/I9 -> 0.13004622 | L9: =D9/($D$2*J9) -> 0.79216413 | M9: 1 | N9: 0.9375 | O9: 2566 | P9: 0 | Q9: 30% Load shedding message received from ALDC
A10: =A9+1 -> 46119 | B10: 27440 | C10: 20057 | D10: 16182 | E10: 15850 | F10: =(IF(ISBLANK(E10),0,E10-C10))/C10 -> -0.20975221 | G10: =D10/($D$2*24) -> 0.14020586 | H10: =D10/($H$2*24) -> 0.17512987 | I10: 6.49 | J10: 4.378 | K10: =(IF(ISBLANK(J10),0,J10-I10))/I10 -> -0.32542373 | L10: =D10/($D$2*J10) -> 0.76860227 | M10: 1 | N10: 0.9306 | O10: 2282 | P10: 0 | Q10: B Phese temporary jamper fail Gss site
A11: =A10+1 -> 46120 | B11: 27440 | C11: 20057 | D11: 26024 | E11: 25550 | F11: =(IF(ISBLANK(E11),0,E11-C11))/C11 -> 0.27386947 | G11: =D11/($D$2*24) -> 0.22548 | H11: =D11/($H$2*24) -> 0.28164502 | I11: 6.49 | J11: 7.118 | K11: =(IF(ISBLANK(J11),0,J11-I11))/I11 -> 0.096764253 | L11: =D11/($D$2*J11) -> 0.76025851 | M11: 1 | N11: 0.881 | O11: 3685 | P11: 0 | Q11: 50% Load shedding message received from ALDC
A12: =A11+1 -> 46121 | B12: 27440 | C12: 20057 | D12: 28769 | E12: 28200 | F12: =(IF(ISBLANK(E12),0,E12-C12))/C12 -> 0.40599292 | G12: =D12/($D$2*24) -> 0.24926353 | H12: =D12/($H$2*24) -> 0.31135281 | I12: 6.49 | J12: 7.078 | K12: =(IF(ISBLANK(J12),0,J12-I12))/I12 -> 0.090600924 | L12: =D12/($D$2*J12) -> 0.84519989 | M12: 1 | N12: 1 | O12: 0 | P12: 0
A13: =A12+1 -> 46122 | B13: 27440 | C13: 20057 | D13: 29198 | E13: 28650 | F13: =(IF(ISBLANK(E13),0,E13-C13))/C13 -> 0.42842898 | G13: =D13/($D$2*24) -> 0.25298052 | H13: =D13/($H$2*24) -> 0.31599567 | I13: 6.49 | J13: 7.173 | K13: =(IF(ISBLANK(J13),0,J13-I13))/I13 -> 0.10523883 | L13: =D13/($D$2*J13) -> 0.84644257 | M13: 1 | N13: 1 | O13: 0 | P13: 0
A14: =A13+1 -> 46123 | B14: 27440 | C14: 20057 | D14: 28613 | E14: 28050 | F14: =(IF(ISBLANK(E14),0,E14-C14))/C14 -> 0.39851423 | G14: =D14/($D$2*24) -> 0.2479119 | H14: =D14/($H$2*24) -> 0.3096645 | I14: 6.49 | J14: 7.065 | K14: =(IF(ISBLANK(J14),0,J14-I14))/I14 -> 0.088597843 | L14: =D14/($D$2*J14) -> 0.84216357 | M14: 1 | N14: 1 | O14: 0 | P14: 0
A15: =A14+1 -> 46124 | B15: 27440 | C15: 20057 | D15: 29186 | E15: 28600 | F15: =(IF(ISBLANK(E15),0,E15-C15))/C15 -> 0.42593608 | G15: =D15/($D$2*24) -> 0.25287655 | H15: =D15/($H$2*24) -> 0.3158658 | I15: 6.49 | J15: 7.236 | K15: =(IF(ISBLANK(J15),0,J15-I15))/I15 -> 0.11494607 | L15: =D15/($D$2*J15) -> 0.8387282 | M15: 1 | N15: 1 | O15: 0 | P15: 0
A16: =A15+1 -> 46125 | B16: 27440 | C16: 20057 | D16: 28719 | E16: 28150 | F16: =(IF(ISBLANK(E16),0,E16-C16))/C16 -> 0.40350002 | G16: =D16/($D$2*24) -> 0.24883032 | H16: =D16/($H$2*24) -> 0.31081169 | I16: 6.49 | J16: 7.155 | K16: =(IF(ISBLANK(J16),0,J16-I16))/I16 -> 0.10246533 | L16: =D16/($D$2*J16) -> 0.83465096 | M16: 1 | N16: 1 | O16: 0 | P16: 0
A17: =A16+1 -> 46126 | B17: 27440 | C17: 20057 | D17: 29834 | E17: 29200 | F17: =(IF(ISBLANK(E17),0,E17-C17))/C17 -> 0.45585083 | G17: =D17/($D$2*24) -> 0.25849102 | H17: =D17/($H$2*24) -> 0.32287879 | I17: 6.49 | J17: 7.376 | K17: =(IF(ISBLANK(J17),0,J17-I17))/I17 -> 0.13651772 | L17: =D17/($D$2*J17) -> 0.84107708 | M17: 1 | N17: 1 | O17: 0 | P17: 0
A18: =A17+1 -> 46127 | B18: 27440 | C18: 20057 | D18: 27481 | E18: 26950 | F18: =(IF(ISBLANK(E18),0,E18-C18))/C18 -> 0.34367054 | G18: =D18/($D$2*24) -> 0.2381039 | H18: =D18/($H$2*24) -> 0.29741342 | I18: 6.49 | J18: 7.089 | K18: =(IF(ISBLANK(J18),0,J18-I18))/I18 -> 0.09229584 | L18: =D18/($D$2*J18) -> 0.80610716 | M18: 1 | N18: 0.9861 | O18: 639 | P18: 0 | Q18: Gss site breckar trip realy testing
A19: =A18+1 -> 46128 | B19: 27440 | C19: 20057 | D19: 29353 | E19: 28750 | F19: =(IF(ISBLANK(E19),0,E19-C19))/C19 -> 0.43341477 | G19: =D19/($D$2*24) -> 0.25432349 | H19: =D19/($H$2*24) -> 0.31767316 | I19: 6.49 | J19: 7.306 | K19: =(IF(ISBLANK(J19),0,J19-I19))/I19 -> 0.1257319 | L19: =D19/($D$2*J19) -> 0.83544536 | M19: 1 | N19: 1 | O19: 0 | P19: 0
A20: =A19+1 -> 46129 | B20: 27440 | C20: 20057 | D20: 29634 | E20: 29000 | F20: =(IF(ISBLANK(E20),0,E20-C20))/C20 -> 0.44587924 | G20: =D20/($D$2*24) -> 0.25675816 | H20: =D20/($H$2*24) -> 0.32071429 | I20: 6.49 | J20: 7.346 | K20: =(IF(ISBLANK(J20),0,J20-I20))/I20 -> 0.13189522 | L20: =D20/($D$2*J20) -> 0.83885051 | M20: 1 | N20: 1 | O20: 0 | P20: 0
A21: =A20+1 -> 46130 | B21: 27440 | C21: 20057 | D21: 30493 | E21: 29850 | F21: =(IF(ISBLANK(E21),0,E21-C21))/C21 -> 0.48825846 | G21: =D21/($D$2*24) -> 0.2642008 | H21: =D21/($H$2*24) -> 0.33001082 | I21: 6.49 | J21: 7.505 | K21: =(IF(ISBLANK(J21),0,J21-I21))/I21 -> 0.15639445 | L21: =D21/($D$2*J21) -> 0.84487932 | M21: 1 | N21: 1 | O21: 0 | P21: 0
A22: =A21+1 -> 46131 | B22: 27440 | C22: 20057 | D22: 29314 | E22: 28650 | F22: =(IF(ISBLANK(E22),0,E22-C22))/C22 -> 0.42842898 | G22: =D22/($D$2*24) -> 0.25398558 | H22: =D22/($H$2*24) -> 0.31725108 | I22: 6.49 | J22: 7.141 | K22: =(IF(ISBLANK(J22),0,J22-I22))/I22 -> 0.10030817 | L22: =D22/($D$2*J22) -> 0.8536135 | M22: 1 | N22: 1 | O22: 0 | P22: 0
A23: =A22+1 -> 46132 | B23: 27440 | C23: 20057 | D23: 29820 | E23: 29200 | F23: =(IF(ISBLANK(E23),0,E23-C23))/C23 -> 0.45585083 | G23: =D23/($D$2*24) -> 0.25836972 | H23: =D23/($H$2*24) -> 0.32272727 | I23: 6.49 | J23: 7.315 | K23: =(IF(ISBLANK(J23),0,J23-I23))/I23 -> 0.12711864 | L23: =D23/($D$2*J23) -> 0.84769287 | M23: 1 | N23: 1 | O23: 0 | P23: 0
A24: =A23+1 -> 46133 | B24: 27440 | C24: 20057 | D24: 30446 | E24: 29850 | F24: =(IF(ISBLANK(E24),0,E24-C24))/C24 -> 0.48825846 | G24: =D24/($D$2*24) -> 0.26379358 | H24: =D24/($H$2*24) -> 0.32950216 | I24: 6.49 | J24: 7.38 | K24: =(IF(ISBLANK(J24),0,J24-I24))/I24 -> 0.13713405 | L24: =D24/($D$2*J24) -> 0.85786531 | M24: 1 | N24: 1 | O24: 0 | P24: 0
A25: =A24+1 -> 46134 | B25: 27440 | C25: 20057 | D25: 30263 | E25: 29600 | F25: =(IF(ISBLANK(E25),0,E25-C25))/C25 -> 0.47579399 | G25: =D25/($D$2*24) -> 0.26220801 | H25: =D25/($H$2*24) -> 0.32752165 | I25: 6.49 | J25: 7.2 | K25: =(IF(ISBLANK(J25),0,J25-I25))/I25 -> 0.10939908 | L25: =D25/($D$2*J25) -> 0.87402671 | M25: 1 | N25: 1 | O25: 0 | P25: 0
A26: =A25+1 -> 46135 | B26: 27440 | C26: 20057 | D26: 28831 | E26: 28350 | F26: =(IF(ISBLANK(E26),0,E26-C26))/C26 -> 0.41347161 | G26: =D26/($D$2*24) -> 0.24980072 | H26: =D26/($H$2*24) -> 0.31202381 | I26: 6.49 | J26: 7.288 | K26: =(IF(ISBLANK(J26),0,J26-I26))/I26 -> 0.1229584 | L26: =D26/($D$2*J26) -> 0.82261489 | M26: 1 | N26: 0.9822 | O26: 781 | P26: 0 | Q26: 20% Load Curtailment message received from SLDC
A27: =A26+1 -> 46136 | B27: 27440 | C27: 20057 | D27: 29473 | E27: 28750 | F27: =(IF(ISBLANK(E27),0,E27-C27))/C27 -> 0.43341477 | G27: =D27/($D$2*24) -> 0.25536321 | H27: =D27/($H$2*24) -> 0.31897186 | I27: 6.49 | J27: 7.108 | K27: =(IF(ISBLANK(J27),0,J27-I27))/I27 -> 0.095223421 | L27: =D27/($D$2*J27) -> 0.86222805 | M27: 1 | N27: 1 | O27: 0 | P27: 0
A28: =A27+1 -> 46137 | B28: 27440 | C28: 20057 | D28: 29055 | E28: 28400 | F28: =(IF(ISBLANK(E28),0,E28-C28))/C28 -> 0.4159645 | G28: =D28/($D$2*24) -> 0.25174153 | H28: =D28/($H$2*24) -> 0.31444805 | I28: 6.49 | J28: 7.154 | K28: =(IF(ISBLANK(J28),0,J28-I28))/I28 -> 0.10231125 | L28: =D28/($D$2*J28) -> 0.84453406 | M28: 1 | N28: 1 | O28: 0 | P28: 0
A29: =A28+1 -> 46138 | B29: 27440 | C29: 20057 | D29: 27959 | E29: 27450 | F29: =(IF(ISBLANK(E29),0,E29-C29))/C29 -> 0.36859949 | G29: =D29/($D$2*24) -> 0.24224544 | H29: =D29/($H$2*24) -> 0.30258658 | I29: 6.49 | J29: 7.33 | K29: =(IF(ISBLANK(J29),0,J29-I29))/I29 -> 0.12942989 | L29: =D29/($D$2*J29) -> 0.7931638 | M29: 1 | N29: 0.9206 | O29: 0 | P29: 1048 | Q29: 20% + 20% Load Curtailment message received from SLDC
A30: =A29+1 -> 46139 | B30: 27440 | C30: 20057 | F30: =(IF(ISBLANK(E30),0,E30-C30))/C30 -> 0 | G30: =D30/($D$2*24) -> 0 | H30: =D30/($H$2*24) -> 0 | I30: 6.49 | K30: =(IF(ISBLANK(J30),0,J30-I30))/I30 -> 0 | L30: =D30/($D$2*J30) -> #DIV/0!
A31: =A30+1 -> 46140 | B31: 27440 | C31: 20057 | F31: =(IF(ISBLANK(E31),0,E31-C31))/C31 -> 0 | G31: =D31/($D$2*24) -> 0 | H31: =D31/($H$2*24) -> 0 | I31: 6.49 | K31: =(IF(ISBLANK(J31),0,J31-I31))/I31 -> 0 | L31: =D31/($D$2*J31) -> #DIV/0!
A32: =A31+1 -> 46141 | B32: 27440 | C32: 20057 | F32: =(IF(ISBLANK(E32),0,E32-C32))/C32 -> 0 | G32: =D32/($D$2*24) -> 0 | H32: =D32/($H$2*24) -> 0 | I32: 6.49 | K32: =(IF(ISBLANK(J32),0,J32-I32))/I32 -> 0 | L32: =D32/($D$2*J32) -> #DIV/0!
A33: =A32+1 -> 46142 | B33: 27440 | C33: 20057 | F33: =(IF(ISBLANK(E33),0,E33-C33))/C33 -> 0 | G33: =D33/($D$2*24) -> 0 | H33: =D33/($H$2*24) -> 0 | I33: 6.49 | K33: =(IF(ISBLANK(J33),0,J33-I33))/I33 -> 0 | L33: =D33/($D$2*J33) -> #DIV/0!
A34: 46113 | B34: =SUM(B4:B33) -> 823200 | C34: =SUM(C4:C33) -> 601710 | D34: =SUM(D4:D33) -> 728251 | E34: =SUM(E4:E33) -> 713450 | F34: =(IF(ISBLANK(E34),0,E34-C34))/C34 -> 0.18570408 | G34: =AVERAGE(G4:G33) -> 0.21032641 | H34: =AVERAGE(H4:H33) -> 0.26271681 | I34: =SUM(I4:I33) -> 194.7 | J34: =SUM(J4:J33) -> 181.293 | K34: =(IF(ISBLANK(J34),0,J34-I34))/I34 -> -0.068859784 | L34: =D34/($D$2*J34) -> 0.83530538 | M34: =AVERAGE(M4:M33) -> 1 | N34: =AVERAGE(N4:N33) -> 0.98367308 | O34: =SUM(O4:O33) -> 12621 | P34: =SUM(P4:P33) -> 1048
A35: 46143 | F35: =(IF(ISBLANK(E35),0,E35-C35))/C35 -> #DIV/0! | G35: =D35/($D$2*24) -> 0 | H35: =D35/($H$2*24) -> 0 | K35: =(IF(ISBLANK(J35),0,J35-I35))/I35 -> #DIV/0! | L35: =D35/($D$2*J35) -> #DIV/0!
A36: =A35+1 -> 46144 | F36: =(IF(ISBLANK(E36),0,E36-C36))/C36 -> #DIV/0! | G36: =D36/($D$2*24) -> 0 | H36: =D36/($H$2*24) -> 0 | K36: =(IF(ISBLANK(J36),0,J36-I36))/I36 -> #DIV/0! | L36: =D36/($D$2*J36) -> #DIV/0!
A37: =A36+1 -> 46145 | F37: =(IF(ISBLANK(E37),0,E37-C37))/C37 -> #DIV/0! | G37: =D37/($D$2*24) -> 0 | H37: =D37/($H$2*24) -> 0 | K37: =(IF(ISBLANK(J37),0,J37-I37))/I37 -> #DIV/0! | L37: =D37/($D$2*J37) -> #DIV/0!
A38: =A37+1 -> 46146 | F38: =(IF(ISBLANK(E38),0,E38-C38))/C38 -> #DIV/0! | G38: =D38/($D$2*24) -> 0 | H38: =D38/($H$2*24) -> 0 | K38: =(IF(ISBLANK(J38),0,J38-I38))/I38 -> #DIV/0! | L38: =D38/($D$2*J38) -> #DIV/0!
A39: =A38+1 -> 46147 | F39: =(IF(ISBLANK(E39),0,E39-C39))/C39 -> #DIV/0! | G39: =D39/($D$2*24) -> 0 | H39: =D39/($H$2*24) -> 0 | K39: =(IF(ISBLANK(J39),0,J39-I39))/I39 -> #DIV/0! | L39: =D39/($D$2*J39) -> #DIV/0!
A40: =A39+1 -> 46148 | F40: =(IF(ISBLANK(E40),0,E40-C40))/C40 -> #DIV/0! | G40: =D40/($D$2*24) -> 0 | H40: =D40/($H$2*24) -> 0 | K40: =(IF(ISBLANK(J40),0,J40-I40))/I40 -> #DIV/0! | L40: =D40/($D$2*J40) -> #DIV/0!
...

Sheet Majethiya
A1: Generation Details_Majethiya Papers Pvt Ltd._Nani Chandur_GJ.
A2: 46113 | B2: DC Capacity (kWp): | D2: 1000 | E2: AC capacity (kWp): | H2: 800 | I2: COD : | K2: 44364
A3: Month | B3: Expected Generation | C3: Guaranteed Generation (kWh) | D3: Inverter Generation (kWh) | E3: ABT Meter Generation at Plant End (kWh) | F3: Generation difference (KWh) | G3: DC-CUF | H3: AC-CUF | I3: Pvsyst Irradiation (kWh/m2) | J3: Actual Irradiation (kWh/m2) | K3: Radiation Difference (KWh/m2) | L3: PR | M3: Plant Availability | N3: Grid Availability | O3: Losses due to Grid Unavailability | P3: Losses due to Plant Unavailability | Q3: Remarks
A4: =A2 -> 46113 | B4: 4631 | C4: 4028 | D4: 5174 | E4: 5175 | F4: =(IF(ISBLANK(E4),0,E4-C4))/C4 -> 0.2847567 | G4: =D4/($D$2*24) -> 0.21558333 | H4: =D4/($H$2*24) -> 0.26947917 | I4: 6.85 | J4: 6.78 | K4: =(IF(ISBLANK(J4),0,J4-I4))/I4 -> -0.010218978 | L4: =D4/($D$2*J4) -> 0.76312684 | M4: 1 | N4: 0.9444 | O4: 1427 | P4: 0 | Q4: 20 % Load curtailment ALDC Request
A5: =A4+1 -> 46114 | B5: 4631 | C5: 4028 | D5: 5087 | E5: 5055 | F5: =(IF(ISBLANK(E5),0,E5-C5))/C5 -> 0.25496524 | G5: =D5/($D$2*24) -> 0.21195833 | H5: =D5/($H$2*24) -> 0.26494792 | I5: 6.85 | J5: 6.51 | K5: =(IF(ISBLANK(J5),0,J5-I5))/I5 -> -0.049635036 | L5: =D5/($D$2*J5) -> 0.78141321 | M5: 1 | N5: 0.9692 | O5: 773 | P5: 0 | Q5: 10 % Load curtailment ALDC Request
A6: =A5+1 -> 46115 | B6: 4631 | C6: 4028 | D6: 4243 | E6: 4230 | F6: =(IF(ISBLANK(E6),0,E6-C6))/C6 -> 0.050148957 | G6: =D6/($D$2*24) -> 0.17679167 | H6: =D6/($H$2*24) -> 0.22098958 | I6: 6.85 | J6: 5.1 | K6: =(IF(ISBLANK(J6),0,J6-I6))/I6 -> -0.25547445 | L6: =D6/($D$2*J6) -> 0.83196078 | M6: 1 | N6: 1 | O6: 0 | P6: 0
A7: =A6+1 -> 46116 | B7: 4631 | C7: 4028 | D7: 6054 | E7: 6045 | F7: =(IF(ISBLANK(E7),0,E7-C7))/C7 -> 0.50074479 | G7: =D7/($D$2*24) -> 0.25225 | H7: =D7/($H$2*24) -> 0.3153125 | I7: 6.85 | J7: 7.65 | K7: =(IF(ISBLANK(J7),0,J7-I7))/I7 -> 0.11678832 | L7: =D7/($D$2*J7) -> 0.79137255 | M7: 1 | N7: 1 | O7: 0 | P7: 0
A8: =A7+1 -> 46117 | B8: 4631 | C8: 4028 | D8: 5598 | E8: 5595 | F8: =(IF(ISBLANK(E8),0,E8-C8))/C8 -> 0.38902681 | G8: =D8/($D$2*24) -> 0.23325 | H8: =D8/($H$2*24) -> 0.2915625 | I8: 6.85 | J8: 6.89 | K8: =(IF(ISBLANK(J8),0,J8-I8))/I8 -> 0.0058394161 | L8: =D8/($D$2*J8) -> 0.81248186 | M8: 1 | N8: 0.8909 | O8: 1550 | P8: 0 | Q8: 30% Load Curtailment ALDC Request
A9: =A8+1 -> 46118 | B9: 4631 | C9: 4028 | D9: 5523 | E9: 5475 | F9: =(IF(ISBLANK(E9),0,E9-C9))/C9 -> 0.35923535 | G9: =D9/($D$2*24) -> 0.230125 | H9: =D9/($H$2*24) -> 0.28765625 | I9: 6.85 | J9: 7.18 | K9: =(IF(ISBLANK(J9),0,J9-I9))/I9 -> 0.048175182 | L9: =D9/($D$2*J9) -> 0.76922006 | M9: 1 | N9: 0.9049 | O9: 1450 | P9: 0 | Q9: 30% Load Curtailment ALDC Request
